Workbook
Name Slicer_Region: #N/A
Name Slicer_Year: #N/A

Sheet territories
A1: TerritoryID | B1: TerritoryDescription | C1: RegionID | D1: Region Description
A2: 1581 | B2: Westboro | C2: 1 | D2: =VLOOKUP(territories[[#This Row],[RegionID]],region[],2,FALSE) -> Eastern
A3: 1730 | B3: Bedford | C3: 1 | D3: =VLOOKUP(territories[[#This Row],[RegionID]],region[],2,FALSE) -> Eastern
A4: 1833 | B4: Georgetow | C4: 1 | D4: =VLOOKUP(territories[[#This Row],[RegionID]],region[],2,FALSE) -> Eastern
A5: 2116 | B5: Boston | C5: 1 | D5: =VLOOKUP(territories[[#This Row],[RegionID]],region[],2,FALSE) -> Eastern
A6: 2139 | B6: Cambridge | C6: 1 | D6: =VLOOKUP(territories[[#This Row],[RegionID]],region[],2,FALSE) -> Eastern
A7: 2184 | B7: Braintree | C7: 1 | D7: =VLOOKUP(territories[[#This Row],[RegionID]],region[],2,FALSE) -> Eastern
A8: 2903 | B8: Providence | C8: 1 | D8: =VLOOKUP(territories[[#This Row],[RegionID]],region[],2,FALSE) -> Eastern
A9: 3049 | B9: Hollis | C9: 3 | D9: =VLOOKUP(territories[[#This Row],[RegionID]],region[],2,FALSE) -> Northern
A10: 3801 | B10: Portsmouth | C10: 3 | D10: =VLOOKUP(territories[[#This Row],[RegionID]],region[],2,FALSE) -> Northern
A11: 6897 | B11: Wilton | C11: 1 | D11: =VLOOKUP(territories[[#This Row],[RegionID]],region[],2,FALSE) -> Eastern
A12: 7960 | B12: Morristown | C12: 1 | D12: =VLOOKUP(territories[[#This Row],[RegionID]],region[],2,FALSE) -> Eastern
A13: 8837 | B13: Edison | C13: 1 | D13: =VLOOKUP(territories[[#This Row],[RegionID]],region[],2,FALSE) -> Eastern
... A54: 98104 | B54: Seattle | C54: 2 | D54: =VLOOKUP(territories[[#This Row],[RegionID]],region[],2,FALSE) -> Westerns

Sheet suppliers
A1: SupplierID | B1: CompanyName | C1: ContactName | D1: ContactTitle | E1: Address | F1: City | G1: Region | H1: PostalCode | I1: Country | J1: Phone | K1: Fax | L1: Supplier Sale | M1: Quantity Supplied
A2: 1 | B2: Exotic Liquids | C2: Charlotte Cooper | D2: Purchasing Manager | E2: 49 Gilbert St. | F2: London | G2: NULL | H2: EC1 4SD | I2: UK | J2: (171) 555-2222 | K2: NULL | L2: =SUMIF(products[SupplierID],suppliers[[#This Row],[SupplierID]],products[[Product Sale ]]) -> 35916.8 | M2: =SUMIF(order_details__2[SupplierID],suppliers[[#This Row],[SupplierID]],order_details__2[Quantity]) -> 2213
A3: 2 | B3: New Orleans Cajun Delights | C3: Shelley Burke | D3: Order Administrator | E3: P.O. Box 78934 | F3: New Orleans | G3: LA | H3: 70117 | I3: USA | J3: (100) 555-4822 | K3: NULL | L3: =SUMIF(products[SupplierID],suppliers[[#This Row],[SupplierID]],products[[Product Sale ]]) -> 33351.95 | M3: =SUMIF(order_details__2[SupplierID],suppliers[[#This Row],[SupplierID]],order_details__2[Quantity]) -> 1735
A4: 3 | B4: Grandma Kelly's Homestead | C4: Regina Murphy | D4: Sales Representative | E4: 707 Oxford Rd. | F4: Ann Arbor | G4: MI | H4: 48104 | I4: USA | J4: (313) 555-5735 | K4: (313) 555-3349 | L4: =SUMIF(products[SupplierID],suppliers[[#This Row],[SupplierID]],products[[Product Sale ]]) -> 43569 | M4: =SUMIF(order_details__2[SupplierID],suppliers[[#This Row],[SupplierID]],order_details__2[Quantity]) -> 1436
A5: 4 | B5: Tokyo Traders | C5: Yoshi Nagase | D5: Marketing Manager | E5: 9-8 Sekimai Musashino-shi | F5: Tokyo | G5: NULL | H5: 100 | I5: Japan | J5: (03) 3555-5011 | K5: NULL | L5: =SUMIF(products[SupplierID],suppliers[[#This Row],[SupplierID]],products[[Product Sale ]]) -> 33533.2 | M5: =SUMIF(order_details__2[SupplierID],suppliers[[#This Row],[SupplierID]],order_details__2[Quantity]) -> 1134
A6: 5 | B6: Cooperativa de Quesos 'Las Cabras' | C6: Antonio del Valle Saavedra | D6: Export Administrator | E6: Calle del Rosal 4 | F6: Oviedo | G6: Asturias | H6: 33007 | I6: Spain | J6: (98) 598 76 54 | K6: NULL | L6: =SUMIF(products[SupplierID],suppliers[[#This Row],[SupplierID]],products[[Product Sale ]]) -> 26768.8 | M6: =SUMIF(order_details__2[SupplierID],suppliers[[#This Row],[SupplierID]],order_details__2[Quantity]) -> 1050
A7: 6 | B7: Mayumi's | C7: Mayumi Ohno | D7: Marketing Representative | E7: 92 Setsuko Chuo-ku | F7: Osaka | G7: NULL | H7: 545 | I7: Japan | J7: (06) 431-7877 | K7: NULL | L7: =SUMIF(products[SupplierID],suppliers[[#This Row],[SupplierID]],products[[Product Sale ]]) -> 15678.3 | M7: =SUMIF(order_details__2[SupplierID],suppliers[[#This Row],[SupplierID]],order_details__2[Quantity]) -> 1417
A8: 7 | B8: Pavlova, Ltd. | C8: Ian Devling | D8: Marketing Manager | E8: 74 Rose St. Moonie Ponds | F8: Melbourne | G8: Victoria | H8: 3058 | I8: Australia | J8: (03) 444-2343 | K8: (03) 444-6588 | L8: =SUMIF(products[SupplierID],suppliers[[#This Row],[SupplierID]],products[[Product Sale ]]) -> 115386.05 | M8: =SUMIF(order_details__2[SupplierID],suppliers[[#This Row],[SupplierID]],order_details__2[Quantity]) -> 3937
A9: 8 | B9: Specialty Biscuits, Ltd. | C9: Peter Wilson | D9: Sales Representative | E9: 29 King's Way | F9: Manchester | G9: NULL | H9: M14 GSD | I9: UK | J9: (161) 555-4448 | K9: NULL | L9: =SUMIF(products[SupplierID],suppliers[[#This Row],[SupplierID]],products[[Product Sale ]]) -> 48793.8 | M9: =SUMIF(order_details__2[SupplierID],suppliers[[#This Row],[SupplierID]],order_details__2[Quantity]) -> 2851
A10: 9 | B10: PB Knckebrd AB | C10: Lars Peterson | D10: Sales Agent | E10: Kaloadagatan 13 | F10: Gteborg | G10: NULL | H10: S-345 67 | I10: Sweden | J10: 031-987 65 43 | K10: 031-987 65 91 | L10: =SUMIF(products[SupplierID],suppliers[[#This Row],[SupplierID]],products[[Product Sale ]]) -> 12072.6 | M10: =SUMIF(order_details__2[SupplierID],suppliers[[#This Row],[SupplierID]],order_details__2[Quantity]) -> 928
A11: 10 | B11: Refrescos Americanas LTDA | C11: Carlos Diaz | D11: Marketing Manager | E11: Av. das Americanas 12.890 | F11: So Paulo | G11: NULL | H11: 5442 | I11: Brazil | J11: (11) 555 4640 | K11: NULL | L11: =SUMIF(products[SupplierID],suppliers[[#This Row],[SupplierID]],products[[Product Sale ]]) -> 4782.6 | M11: =SUMIF(order_details__2[SupplierID],suppliers[[#This Row],[SupplierID]],order_details__2[Quantity]) -> 1125
A12: 11 | B12: Heli Swaren GmbH & Co. KG | C12: Petra Winkler | D12: Sales Manager | E12: Tiergartenstrae 5 | F12: Berlin | G12: NULL | H12: 10785 | I12: Germany | J12: (010) 9984510 | K12: NULL | L12: =SUMIF(products[SupplierID],suppliers[[#This Row],[SupplierID]],products[[Product Sale ]]) -> 40818 | M12: =SUMIF(order_details__2[SupplierID],suppliers[[#This Row],[SupplierID]],order_details__2[Quantity]) -> 1436
A13: 12 | B13: Plutzer Lebensmittelgromrkte AG | C13: Martin Bein | D13: International Marketing Mgr. | E13: Bogenallee 51 | F13: Frankfurt | G13: NULL | H13: 60439 | I13: Germany | J13: (069) 992755 | K13: NULL | L13: =SUMIF(products[SupplierID],suppliers[[#This Row],[SupplierID]],products[[Product Sale ]]) -> 155946.55 | M13: =SUMIF(order_details__2[SupplierID],suppliers[[#This Row],[SupplierID]],order_details__2[Quantity]) -> 4072
... A30: 29 | B30: Forts d'rables | C30: Chantal Goulet | D30: Accounting Manager | E30: 148 rue Chasseur | F30: Ste-Hyacinthe | G30: Qubec | H30: J2S 7S8 | I30: Canada | J30: (514) 555-2955 | K30: (514) 555-2921 | L30: =SUMIF(products[SupplierID],suppliers[[#This Row],[SupplierID]],products[[Product Sale ]]) -> 66266.7 | M30: =SUMIF(order_details__2[SupplierID],suppliers[[#This Row],[SupplierID]],order_details__2[Quantity]) -> 1686

Sheet supplier_pivot
A3: Row Labels | B3: Sum of Quantity Supplied | I3: *
A4: Leka Trading | B4: 1878
A5: New England Seafood Cannery | B5: 2084
A6: G'day, Mate | B6: 2108
A7: Exotic Liquids | B7: 2213
A8: Formaggi Fortini s.r.l. | B8: 2500
A9: Norske Meierier | B9: 2526
A10: Specialty Biscuits, Ltd. | B10: 2851
A11: Gai pturage | B11: 3073
A12: Pavlova, Ltd. | B12: 3937
A13: Plutzer Lebensmittelgromrkte AG | B13: 4072
A14: Grand Total | B14: 27242
A36: Row Labels | B36: Sum of Supplier Sale
A37: Norske Meierier | B37: 46897.2
A38: Specialty Biscuits, Ltd. | B38: 48793.8
A39: Formaggi Fortini s.r.l. | B39: 51082.5
A40: Pasta Buttini s.r.l. | B40: 52929
A41: Forts d'rables | B41: 66266.7
A42: G'day, Mate | B42: 69636.6
A43: Pavlova, Ltd. | B43: 115386.05
A44: Gai pturage | B44: 126582
A45: Plutzer Lebensmittelgromrkte AG | B45: 155946.55
A46: Aux joyeux ecclsiastiques | B46: 163135
A47: Grand Total | B47: 896655.4

Sheet shippers
A1: ShipperID | B1: CompanyName | C1: Phone | D1: Products Supplied | E1: Total Freight
A2: 1 | B2: Speedy Express | C2: (503) 555-9831 | D2: =SUMIF(Table15[ShipID],shippers[[#This Row],[ShipperID]],Table15[[OrderQuantity ]]) -> 15919 | E2: =SUMIF(orders[ShipVia],shippers[[#This Row],[ShipperID]],orders[Freight]) -> 16185.33
A3: 2 | B3: United Package | C3: (503) 555-3199 | D3: =SUMIF(Table15[ShipID],shippers[[#This Row],[ShipperID]],Table15[[OrderQuantity ]]) -> 19945 | E3: =SUMIF(orders[ShipVia],shippers[[#This Row],[ShipperID]],orders[Freight]) -> 28230.88
A4: 3 | B4: Federal Shipping | C4: (503) 555-9931 | D4: =SUMIF(Table15[ShipID],shippers[[#This Row],[ShipperID]],Table15[[OrderQuantity ]]) -> 15453 | E4: =SUMIF(orders[ShipVia],shippers[[#This Row],[ShipperID]],orders[Freight]) -> 20512.51

Sheet region
A1: RegionID | B1: RegionDescription
A2: 1 | B2: Eastern
A3: 2 | B3: Westerns
A4: 3 | B4: Northern
A5: 4 | B5: Southern

Sheet products
A1: ProductID | B1: ProductName | C1: SupplierID | D1: CategoryID | E1: QuantityPerUnit | F1: UnitPrice | G1: UnitsInStock | H1: UnitsOnOrder | I1: ReorderLevel | J1: Discontinued | K1: Product Sale | L1: QuantitySale
A2: 1 | B2: Chai | C2: 1 | D2: 1 | E2: 10 boxes x 20 bags | F2: 18 | G2: 39 | H2: 0 | I2: 10 | J2: 0 | K2: =SUMIF(order_details__2[ProductID],products[[#This Row],[ProductID]],order_details__2[Line Sale]) -> 14277.6 | L2: =SUMIF(order_details__2[ProductID],products[[#This Row],[ProductID]],order_details__2[Quantity]) -> 828
A3: 2 | B3: Chang | C3: 1 | D3: 1 | E3: 24 - 12 oz bottles | F3: 19 | G3: 17 | H3: 40 | I3: 25 | J3: 0 | K3: =SUMIF(order_details__2[ProductID],products[[#This Row],[ProductID]],order_details__2[Line Sale]) -> 18559.2 | L3: =SUMIF(order_details__2[ProductID],products[[#This Row],[ProductID]],order_details__2[Quantity]) -> 1057
A4: 3 | B4: Aniseed Syrup | C4: 1 | D4: 2 | E4: 12 - 550 ml bottles | F4: 10 | G4: 13 | H4: 70 | I4: 25 | J4: 0 | K4: =SUMIF(order_details__2[ProductID],products[[#This Row],[ProductID]],order_details__2[Line Sale]) -> 3080 | L4: =SUMIF(order_details__2[ProductID],products[[#This Row],[ProductID]],order_details__2[Quantity]) -> 328
A5: 4 | B5: Chef Anton's Cajun Seasoning | C5: 2 | D5: 2 | E5: 48 - 6 oz jars | F5: 22 | G5: 53 | H5: 0 | I5: 0 | J5: 0 | K5: =SUMIF(order_details__2[ProductID],products[[#This Row],[ProductID]],order_details__2[Line Sale]) -> 9424.8 | L5: =SUMIF(order_details__2[ProductID],products[[#This Row],[ProductID]],order_details__2[Quantity]) -> 453
A6: 5 | B6: Chef Anton's Gumbo Mix | C6: 2 | D6: 2 | E6: 36 boxes | F6: 21.35 | G6: 0 | H6: 0 | I6: 0 | J6: 1 | K6: =SUMIF(order_details__2[ProductID],products[[#This Row],[ProductID]],order_details__2[Line Sale]) -> 5801.15 | L6: =SUMIF(order_details__2[ProductID],products[[#This Row],[ProductID]],order_details__2[Quantity]) -> 298
A7: 6 | B7: Grandma's Boysenberry Spread | C7: 3 | D7: 2 | E7: 12 - 8 oz jars | F7: 25 | G7: 120 | H7: 0 | I7: 25 | J7: 0 | K7: =SUMIF(order_details__2[ProductID],products[[#This Row],[ProductID]],order_details__2[Line Sale]) -> 7345 | L7: =SUMIF(order_details__2[ProductID],products[[#This Row],[ProductID]],order_details__2[Quantity]) -> 301
A8: 7 | B8: Uncle Bob's Organic Dried Pears | C8: 3 | D8: 7 | E8: 12 - 1 lb pkgs. | F8: 30 | G8: 15 | H8: 0 | I8: 10 | J8: 0 | K8: =SUMIF(order_details__2[ProductID],products[[#This Row],[ProductID]],order_details__2[Line Sale]) -> 22464 | L8: =SUMIF(order_details__2[ProductID],products[[#This Row],[ProductID]],order_details__2[Quantity]) -> 763
A9: 8 | B9: Northwoods Cranberry Sauce | C9: 3 | D9: 2 | E9: 12 - 12 oz jars | F9: 40 | G9: 6 | H9: 0 | I9: 0 | J9: 0 | K9: =SUMIF(order_details__2[ProductID],products[[#This Row],[ProductID]],order_details__2[Line Sale]) -> 13760 | L9: =SUMIF(order_details__2[ProductID],products[[#This Row],[ProductID]],order_details__2[Quantity]) -> 372
A10: 9 | B10: Mishi Kobe Niku | C10: 4 | D10: 6 | E10: 18 - 500 g pkgs. | F10: 97 | G10: 29 | H10: 0 | I10: 0 | J10: 1 | K10: =SUMIF(order_details__2[ProductID],products[[#This Row],[ProductID]],order_details__2[Line Sale]) -> 8827 | L10: =SUMIF(order_details__2[ProductID],products[[#This Row],[ProductID]],order_details__2[Quantity]) -> 95
A11: 10 | B11: Ikura | C11: 4 | D11: 8 | E11: 12 - 200 ml jars | F11: 31 | G11: 31 | H11: 0 | I11: 0 | J11: 0 | K11: =SUMIF(order_details__2[ProductID],products[[#This Row],[ProductID]],order_details__2[Line Sale]) -> 22140.2 | L11: =SUMIF(order_details__2[ProductID],products[[#This Row],[ProductID]],order_details__2[Quantity]) -> 742
A12: 11 | B12: Queso Cabrales | C12: 5 | D12: 4 | E12: 1 kg pkg. | F12: 21 | G12: 22 | H12: 30 | I12: 30 | J12: 0 | K12: =SUMIF(order_details__2[ProductID],products[[#This Row],[ProductID]],order_details__2[Line Sale]) -> 13902 | L12: =SUMIF(order_details__2[ProductID],products[[#This Row],[ProductID]],order_details__2[Quantity]) -> 706
A13: 12 | B13: Queso Manchego La Pastora | C13: 5 | D13: 4 | E13: 10 - 500 g pkgs. | F13: 38 | G13: 86 | H13: 0 | I13: 0 | J13: 0 | K13: =SUMIF(order_details__2[ProductID],products[[#This Row],[ProductID]],order_details__2[Line Sale]) -> 12866.8 | L13: =SUMIF(order_details__2[ProductID],products[[#This Row],[ProductID]],order_details__2[Quantity]) -> 344
... A78: 77 | B78: Original Frankfurter grne Soe | C78: 12 | D78: 2 | E78: 12 boxes | F78: 13 | G78: 32 | H78: 0 | I78: 15 | J78: 0 | K78: =SUMIF(order_details__2[ProductID],products[[#This Row],[ProductID]],order_details__2[Line Sale]) -> 9685 | L78: =SUMIF(order_details__2[ProductID],products[[#This Row],[ProductID]],order_details__2[Quantity]) -> 791

Sheet product_pivot
A3: Row Labels | B3: Sum of QuantitySale
A4: Flotemysost | B4: 1057
A5: Chang | B5: 1057
A6: Tarte au sucre | B6: 1083
A7: Boston Crab Meat | B7: 1103
A8: Guaran Fantstica | B8: 1125
A9: Rhnbru Klosterbier | B9: 1155
A10: Pavlova | B10: 1158
A11: Gnocchi di nonna Alice | B11: 1263
A12: Gorgonzola Telino | B12: 1397
A13: Raclette Courdavault | B13: 1496
A14: Camembert Pierrot | B14: 1577
A15: Grand Total | B15: 13471
A23: Row Labels | B23: Sum of Product Sale
A24: Rssle Sauerkraut | B24: 26865.6
A25: Carnarvon Tigers | B25: 31987.5
A26: Alice Mutton | B26: 35482.2
A27: Manjimup Dried Apples | B27: 44742.6
A28: Gnocchi di nonna Alice | B28: 45121.2
A29: Tarte au sucre | B29: 49827.9
A30: Camembert Pierrot | B30: 50286
A31: Raclette Courdavault | B31: 76296
A32: Thringer Rostbratwurst | B32: 87736.4
A33: Cte de Blaye | B33: 149984.2
A34: Grand Total | B34: 598329.6

Sheet orders
A1: OrderID | B1: CustomerID | C1: EmployeeID | D1: OrderDate | E1: RequiredDate | F1: ShippedDate | G1: ShipVia | H1: Freight | I1: ShipName | J1: ShipAddress | K1: ShipCity | L1: ShipRegion | M1: ShipPostalCode | N1: ShipCountry | O1: OrderQuantity | P1: Order Sale | Q1: Territory | R1: Region | S1: Shipper | T1: Year | U1: Month
A2: 10248 | B2: VINET | C2: 5 | D2: 35250 | E2: 35278 | F2: 35262 | G2: 3 | H2: 32.38 | I2: Vins et alcools Chevalier | J2: 59 rue de l-Abbaye | K2: Reims | L2: NULL | M2: 51100 | N2: France | O2: =VLOOKUP(orders[[#This Row],[OrderID]],Table15[],4,FALSE) -> 27 | P2: =VLOOKUP(orders[[#This Row],[OrderID]],Table15[],2,FALSE) -> 440 | Q2: =VLOOKUP(orders[[#This Row],[EmployeeID]],employee_territory[],2,FALSE) -> 2903 | R2: =VLOOKUP(orders[[#This Row],[Territory]],territories[],4,FALSE) -> Eastern | S2: =VLOOKUP(orders[[#This Row],[ShipVia]],shippers[],2,FALSE) -> Federal Shipping | T2: =YEAR(orders[[#This Row],[OrderDate]]) -> 1996 | U2: =MONTH(orders[[#This Row],[OrderDate]]) -> 7
A3: 10249 | B3: TOMSP | C3: 6 | D3: 35251 | E3: 35293 | F3: 35256 | G3: 1 | H3: 11.61 | I3: Toms Spezialitten | J3: Luisenstr. 48 | K3: Mnster | L3: NULL | M3: 44087 | N3: Germany | O3: =VLOOKUP(orders[[#This Row],[OrderID]],Table15[],4,FALSE) -> 49 | P3: =VLOOKUP(orders[[#This Row],[OrderID]],Table15[],2,FALSE) -> 1863.4 | Q3: =VLOOKUP(orders[[#This Row],[EmployeeID]],employee_territory[],2,FALSE) -> 85014 | R3: =VLOOKUP(orders[[#This Row],[Territory]],territories[],4,FALSE) -> Westerns | S3: =VLOOKUP(orders[[#This Row],[ShipVia]],shippers[],2,FALSE) -> Speedy Express | T3: =YEAR(orders[[#This Row],[OrderDate]]) -> 1996 | U3: =MONTH(orders[[#This Row],[OrderDate]]) -> 7
A4: 10250 | B4: HANAR | C4: 4 | D4: 35254 | E4: 35282 | F4: 35258 | G4: 2 | H4: 65.83 | I4: Hanari Carnes | J4: Rua do Pao, 67 | K4: Rio de Janeiro | L4: RJ | M4: 05454-876 | N4: Brazil | O4: =VLOOKUP(orders[[#This Row],[OrderID]],Table15[],4,FALSE) -> 60 | P4: =VLOOKUP(orders[[#This Row],[OrderID]],Table15[],2,FALSE) -> 1813 | Q4: =VLOOKUP(orders[[#This Row],[EmployeeID]],employee_territory[],2,FALSE) -> 20852 | R4: =VLOOKUP(orders[[#This Row],[Territory]],territories[],4,FALSE) -> Eastern | S4: =VLOOKUP(orders[[#This Row],[ShipVia]],shippers[],2,FALSE) -> United Package | T4: =YEAR(orders[[#This Row],[OrderDate]]) -> 1996 | U4: =MONTH(orders[[#This Row],[OrderDate]]) -> 7
A5: 10251 | B5: VICTE | C5: 3 | D5: 35254 | E5: 35282 | F5: 35261 | G5: 1 | H5: 41.34 | I5: Victuailles en stock | J5: 2, rue du Commerce | K5: Lyon | L5: NULL | M5: 69004 | N5: France | O5: =VLOOKUP(orders[[#This Row],[OrderID]],Table15[],4,FALSE) -> 41 | P5: =VLOOKUP(orders[[#This Row],[OrderID]],Table15[],2,FALSE) -> 670.8 | Q5: =VLOOKUP(orders[[#This Row],[EmployeeID]],employee_territory[],2,FALSE) -> 30346 | R5: =VLOOKUP(orders[[#This Row],[Territory]],territories[],4,FALSE) -> Southern | S5: =VLOOKUP(orders[[#This Row],[ShipVia]],shippers[],2,FALSE) -> Speedy Express | T5: =YEAR(orders[[#This Row],[OrderDate]]) -> 1996 | U5: =MONTH(orders[[#This Row],[OrderDate]]) -> 7
A6: 10252 | B6: SUPRD | C6: 4 | D6: 35255 | E6: 35283 | F6: 35257 | G6: 2 | H6: 51.3 | I6: Suprmes dlices | J6: Boulevard Tirou, 255 | K6: Charleroi | L6: NULL | M6: B-6000 | N6: Belgium | O6: =VLOOKUP(orders[[#This Row],[OrderID]],Table15[],4,FALSE) -> 105 | P6: =VLOOKUP(orders[[#This Row],[OrderID]],Table15[],2,FALSE) -> 3730 | Q6: =VLOOKUP(orders[[#This Row],[EmployeeID]],employee_territory[],2,FALSE) -> 20852 | R6: =VLOOKUP(orders[[#This Row],[Territory]],territories[],4,FALSE) -> Eastern | S6: =VLOOKUP(orders[[#This Row],[ShipVia]],shippers[],2,FALSE) -> United Package | T6: =YEAR(orders[[#This Row],[OrderDate]]) -> 1996 | U6: =MONTH(orders[[#This Row],[OrderDate]]) -> 7
A7: 10253 | B7: HANAR | C7: 3 | D7: 35256 | E7: 35270 | F7: 35262 | G7: 2 | H7: 58.17 | I7: Hanari Carnes | J7: Rua do Pao, 67 | K7: Rio de Janeiro | L7: RJ | M7: 05454-876 | N7: Brazil | O7: =VLOOKUP(orders[[#This Row],[OrderID]],Table15[],4,FALSE) -> 102 | P7: =VLOOKUP(orders[[#This Row],[OrderID]],Table15[],2,FALSE) -> 1444.8 | Q7: =VLOOKUP(orders[[#This Row],[EmployeeID]],employee_territory[],2,FALSE) -> 30346 | R7: =VLOOKUP(orders[[#This Row],[Territory]],territories[],4,FALSE) -> Southern | S7: =VLOOKUP(orders[[#This Row],[ShipVia]],shippers[],2,FALSE) -> United Package | T7: =YEAR(orders[[#This Row],[OrderDate]]) -> 1996 | U7: =MONTH(orders[[#This Row],[OrderDate]]) -> 7
A8: 10254 | B8: CHOPS | C8: 5 | D8: 35257 | E8: 35285 | F8: 35269 | G8: 2 | H8: 22.98 | I8: Chop-suey Chinese | J8: Hauptstr. 31 | K8: Bern | L8: NULL | M8: 3012 | N8: Switzerland | O8: =VLOOKUP(orders[[#This Row],[OrderID]],Table15[],4,FALSE) -> 57 | P8: =VLOOKUP(orders[[#This Row],[OrderID]],Table15[],2,FALSE) -> 625.2 | Q8: =VLOOKUP(orders[[#This Row],[EmployeeID]],employee_territory[],2,FALSE) -> 2903 | R8: =VLOOKUP(orders[[#This Row],[Territory]],territories[],4,FALSE) -> Eastern | S8: =VLOOKUP(orders[[#This Row],[ShipVia]],shippers[],2,FALSE) -> United Package | T8: =YEAR(orders[[#This Row],[OrderDate]]) -> 1996 | U8: =MONTH(orders[[#This Row],[OrderDate]]) -> 7
A9: 10255 | B9: RICSU | C9: 9 | D9: 35258 | E9: 35286 | F9: 35261 | G9: 3 | H9: 148.33 | I9: Richter Supermarkt | J9: Starenweg 5 | K9: Genve | L9: NULL | M9: 1204 | N9: Switzerland | O9: =VLOOKUP(orders[[#This Row],[OrderID]],Table15[],4,FALSE) -> 110 | P9: =VLOOKUP(orders[[#This Row],[OrderID]],Table15[],2,FALSE) -> 2490.5 | Q9: =VLOOKUP(orders[[#This Row],[EmployeeID]],employee_territory[],2,FALSE) -> 3049 | R9: =VLOOKUP(orders[[#This Row],[Territory]],territories[],4,FALSE) -> Northern | S9: =VLOOKUP(orders[[#This Row],[ShipVia]],shippers[],2,FALSE) -> Federal Shipping | T9: =YEAR(orders[[#This Row],[OrderDate]]) -> 1996 | U9: =MONTH(orders[[#This Row],[OrderDate]]) -> 7
A10: 10256 | B10: WELLI | C10: 3 | D10: 35261 | E10: 35289 | F10: 35263 | G10: 2 | I10: Wellington Importadora | J10: Rua do Mercado, 12 | K10: Resende | L10: SP | M10: 08737-363 | N10: Brazil | O10: =VLOOKUP(orders[[#This Row],[OrderID]],Table15[],4,FALSE) -> 27 | P10: =VLOOKUP(orders[[#This Row],[OrderID]],Table15[],2,FALSE) -> 517.8 | Q10: =VLOOKUP(orders[[#This Row],[EmployeeID]],employee_territory[],2,FALSE) -> 30346 | R10: =VLOOKUP(orders[[#This Row],[Territory]],territories[],4,FALSE) -> Southern | S10: =VLOOKUP(orders[[#This Row],[ShipVia]],shippers[],2,FALSE) -> United Package | T10: =YEAR(orders[[#This Row],[OrderDate]]) -> 1996 | U10: =MONTH(orders[[#This Row],[OrderDate]]) -> 7
A11: 10257 | B11: HILAA | C11: 4 | D11: 35262 | E11: 35290 | F11: 35268 | G11: 3 | H11: 81.91 | I11: HILARION-Abastos | J11: Carrera 22 con Ave. Carlos Soublette #8-35 | K11: San Cristbal | L11: Tchira | M11: 5022 | N11: Venezuela | O11: =VLOOKUP(orders[[#This Row],[OrderID]],Table15[],4,FALSE) -> 46 | P11: =VLOOKUP(orders[[#This Row],[OrderID]],Table15[],2,FALSE) -> 1119.9 | Q11: =VLOOKUP(orders[[#This Row],[EmployeeID]],employee_territory[],2,FALSE) -> 20852 | R11: =VLOOKUP(orders[[#This Row],[Territory]],territories[],4,FALSE) -> Eastern | S11: =VLOOKUP(orders[[#This Row],[ShipVia]],shippers[],2,FALSE) -> Federal Shipping | T11: =YEAR(orders[[#This Row],[OrderDate]]) -> 1996 | U11: =MONTH(orders[[#This Row],[OrderDate]]) -> 7
A12: 10258 | B12: ERNSH | C12: 1 | D12: 35263 | E12: 35291 | F12: 35269 | G12: 1 | H12: 140.51 | I12: Ernst Handel | J12: Kirchgasse 6 | K12: Graz | L12: NULL | M12: 8010 | N12: Austria | O12: =VLOOKUP(orders[[#This Row],[OrderID]],Table15[],4,FALSE) -> 121 | P12: =VLOOKUP(orders[[#This Row],[OrderID]],Table15[],2,FALSE) -> 2018.6 | Q12: =VLOOKUP(orders[[#This Row],[EmployeeID]],employee_territory[],2,FALSE) -> 6897 | R12: =VLOOKUP(orders[[#This Row],[Territory]],territories[],4,FALSE) -> Eastern | S12: =VLOOKUP(orders[[#This Row],[ShipVia]],shippers[],2,FALSE) -> Speedy Express | T12: =YEAR(orders[[#This Row],[OrderDate]]) -> 1996 | U12: =MONTH(orders[[#This Row],[OrderDate]]) -> 7
A13: 10259 | B13: CENTC | C13: 4 | D13: 35264 | E13: 35292 | F13: 35271 | G13: 3 | H13: 3.25 | I13: Centro comercial Moctezuma | J13: Sierras de Granada 9993 | K13: Mxico D.F. | L13: NULL | M13: 5022 | N13: Mexico | O13: =VLOOKUP(orders[[#This Row],[OrderID]],Table15[],4,FALSE) -> 11 | P13: =VLOOKUP(orders[[#This Row],[OrderID]],Table15[],2,FALSE) -> 100.8 | Q13: =VLOOKUP(orders[[#This Row],[EmployeeID]],employee_territory[],2,FALSE) -> 20852 | R13: =VLOOKUP(orders[[#This Row],[Territory]],territories[],4,FALSE) -> Eastern | S13: =VLOOKUP(orders[[#This Row],[ShipVia]],shippers[],2,FALSE) -> Federal Shipping | T13: =YEAR(orders[[#This Row],[OrderDate]]) -> 1996 | U13: =MONTH(orders[[#This Row],[OrderDate]]) -> 7
A14: 10260 | B14: OTTIK | C14: 4 | D14: 35265 | E14: 35293 | F14: 35275 | G14: 1 | H14: 55.09 | I14: Ottilies Kseladen | J14: Mehrheimerstr. 369 | K14: Kln | L14: NULL | M14: 50739 | N14: Germany | O14: =VLOOKUP(orders[[#This Row],[OrderID]],Table15[],4,FALSE) -> 102 | P14: =VLOOKUP(orders[[#This Row],[OrderID]],Table15[],2,FALSE) -> 1746.2 | Q14: =VLOOKUP(orders[[#This Row],[EmployeeID]],employee_territory[],2,FALSE) -> 20852 | R14: =VLOOKUP(orders[[#This Row],[Territory]],territories[],4,FALSE) -> Eastern | S14: =VLOOKUP(orders[[#This Row],[ShipVia]],shippers[],2,FALSE) -> Speedy Express | T14: =YEAR(orders[[#This Row],[OrderDate]]) -> 1996 | U14: =MONTH(orders[[#This Row],[OrderDate]]) -> 7
A15: 10261 | B15: QUEDE | C15: 4 | D15: 35265 | E15: 35293 | F15: 35276 | G15: 2 | H15: 3.05 | I15: Que Delcia | J15: Rua da Panificadora, 12 | K15: Rio de Janeiro | L15: RJ | M15: 02389-673 | N15: Brazil | O15: =VLOOKUP(orders[[#This Row],[OrderID]],Table15[],4,FALSE) -> 40 | P15: =VLOOKUP(orders[[#This Row],[OrderID]],Table15[],2,FALSE) -> 448 | Q15: =VLOOKUP(orders[[#This Row],[EmployeeID]],employee_territory[],2,FALSE) -> 20852 | R15: =VLOOKUP(orders[[#This Row],[Territory]],territories[],4,FALSE) -> Eastern | S15: =VLOOKUP(orders[[#This Row],[ShipVia]],shippers[],2,FALSE) -> United Package | T15: =YEAR(orders[[#This Row],[OrderDate]]) -> 1996 | U15: =MONTH(orders[[#This Row],[OrderDate]]) -> 7
A16: 10262 | B16: RATTC | C16: 8 | D16: 35268 | E16: 35296 | F16: 35271 | G16: 3 | H16: 48.29 | I16: Rattlesnake Canyon Grocery | J16: 2817 Milton Dr. | K16: Albuquerque | L16: NM | M16: 87110 | N16: USA | O16: =VLOOKUP(orders[[#This Row],[OrderID]],Table15[],4,FALSE) -> 29 | P16: =VLOOKUP(orders[[#This Row],[OrderID]],Table15[],2,FALSE) -> 624.8 | Q16: =VLOOKUP(orders[[#This Row],[EmployeeID]],employee_territory[],2,FALSE) -> 19428 | R16: =VLOOKUP(orders[[#This Row],[Territory]],territories[],4,FALSE) -> Northern | S16: =VLOOKUP(orders[[#This Row],[ShipVia]],shippers[],2,FALSE) -> Federal Shipping | T16: =YEAR(orders[[#This Row],[OrderDate]]) -> 1996 | U16: =MONTH(orders[[#This Row],[OrderDate]]) -> 7
A17: 10263 | B17: ERNSH | C17: 9 | D17: 35269 | E17: 35297 | F17: 35277 | G17: 3 | H17: 146.06 | I17: Ernst Handel | J17: Kirchgasse 6 | K17: Graz | L17: NULL | M17: 8010 | N17: Austria | O17: =VLOOKUP(orders[[#This Row],[OrderID]],Table15[],4,FALSE) -> 184 | P17: =VLOOKUP(orders[[#This Row],[OrderID]],Table15[],2,FALSE) -> 2464.8 | Q17: =VLOOKUP(orders[[#This Row],[EmployeeID]],employee_territory[],2,FALSE) -> 3049 | R17: =VLOOKUP(orders[[#This Row],[Territory]],territories[],4,FALSE) -> Northern | S17: =VLOOKUP(orders[[#This Row],[ShipVia]],shippers[],2,FALSE) -> Federal Shipping | T17: =YEAR(orders[[#This Row],[OrderDate]]) -> 1996 | U17: =MONTH(orders[[#This Row],[OrderDate]]) -> 7
A18: 10264 | B18: FOLKO | C18: 6 | D18: 35270 | E18: 35298 | F18: 35300 | G18: 3 | H18: 3.67 | I18: Folk och f HB | J18: kergatan 24 | K18: Brcke | L18: NULL | M18: S-844 67 | N18: Sweden | O18: =VLOOKUP(orders[[#This Row],[OrderID]],Table15[],4,FALSE) -> 60 | P18: =VLOOKUP(orders[[#This Row],[OrderID]],Table15[],2,FALSE) -> 724.5 | Q18: =VLOOKUP(orders[[#This Row],[EmployeeID]],employee_territory[],2,FALSE) -> 85014 | R18: =VLOOKUP(orders[[#This Row],[Territory]],territories[],4,FALSE) -> Westerns | S18: =VLOOKUP(orders[[#This Row],[ShipVia]],shippers[],2,FALSE) -> Federal Shipping | T18: =YEAR(orders[[#This Row],[OrderDate]]) -> 1996 | U18: =MONTH(orders[[#This Row],[OrderDate]]) -> 7
A19: 10265 | B19: BLONP | C19: 2 | D19: 35271 | E19: 35299 | F19: 35289 | G19: 1 | H19: 55.28 | I19: Blondel pre et fils | J19: 24, place Klber | K19: Strasbourg | L19: NULL | M19: 67000 | N19: France | O19: =VLOOKUP(orders[[#This Row],[OrderID]],Table15[],4,FALSE) -> 50 | P19: =VLOOKUP(orders[[#This Row],[OrderID]],Table15[],2,FALSE) -> 1176 | Q19: =VLOOKUP(orders[[#This Row],[EmployeeID]],employee_territory[],2,FALSE) -> 1581 | R19: =VLOOKUP(orders[[#This Row],[Territory]],territories[],4,FALSE) -> Eastern | S19: =VLOOKUP(orders[[#This Row],[ShipVia]],shippers[],2,FALSE) -> Speedy Express | T19: =YEAR(orders[[#This Row],[OrderDate]]) -> 1996 | U19: =MONTH(orders[[#This Row],[OrderDate]]) -> 7
A20: 10266 | B20: WARTH | C20: 3 | D20: 35272 | E20: 35314 | F20: 35277 | G20: 3 | H20: 25.73 | I20: Wartian Herkku | J20: Torikatu 38 | K20: Oulu | L20: NULL | M20: 90110 | N20: Finland | O20: =VLOOKUP(orders[[#This Row],[OrderID]],Table15[],4,FALSE) -> 12 | P20: =VLOOKUP(orders[[#This Row],[OrderID]],Table15[],2,FALSE) -> 364.8 | Q20: =VLOOKUP(orders[[#This Row],[EmployeeID]],employee_territory[],2,FALSE) -> 30346 | R20: =VLOOKUP(orders[[#This Row],[Territory]],territories[],4,FALSE) -> Southern | S20: =VLOOKUP(orders[[#This Row],[ShipVia]],shippers[],2,FALSE) -> Federal Shipping | T20: =YEAR(orders[[#This Row],[OrderDate]]) -> 1996 | U20: =MONTH(orders[[#This Row],[OrderDate]]) -> 7
A21: 10267 | B21: FRANK | C21: 4 | D21: 35275 | E21: 35303 | F21: 35283 | G21: 1 | H21: 208.58 | I21: Frankenversand | J21: Berliner Platz 43 | K21: Mnchen | L21: NULL | M21: 80805 | N21: Germany | O21: =VLOOKUP(orders[[#This Row],[OrderID]],Table15[],4,FALSE) -> 135 | P21: =VLOOKUP(orders[[#This Row],[OrderID]],Table15[],2,FALSE) -> 4031 | Q21: =VLOOKUP(orders[[#This Row],[EmployeeID]],employee_territory[],2,FALSE) -> 20852 | R21: =VLOOKUP(orders[[#This Row],[Territory]],territories[],4,FALSE) -> Eastern | S21: =VLOOKUP(orders[[#This Row],[ShipVia]],shippers[],2,FALSE) -> Speedy Express | T21: =YEAR(orders[[#This Row],[OrderDate]]) -> 1996 | U21: =MONTH(orders[[#This Row],[OrderDate]]) -> 7
A22: 10268 | B22: GROSR | C22: 8 | D22: 35276 | E22: 35304 | F22: 35279 | G22: 3 | H22: 66.29 | I22: GROSELLA-Restaurante | J22: 5 Ave. Los Palos Grandes | K22: Caracas | L22: DF | M22: 1081 | N22: Venezuela | O22: =VLOOKUP(orders[[#This Row],[OrderID]],Table15[],4,FALSE) -> 14 | P22: =VLOOKUP(orders[[#This Row],[OrderID]],Table15[],2,FALSE) -> 1101.2 | Q22: =VLOOKUP(orders[[#This Row],[EmployeeID]],employee_territory[],2,FALSE) -> 19428 | R22: =VLOOKUP(orders[[#This Row],[Territory]],territories[],4,FALSE) -> Northern | S22: =VLOOKUP(orders[[#This Row],[ShipVia]],shippers[],2,FALSE) -> Federal Shipping | T22: =YEAR(orders[[#This Row],[OrderDate]]) -> 1996 | U22: =MONTH(orders[[#This Row],[OrderDate]]) -> 7
... A761: 11007 | B761: PRINI | C761: 8 | D761: 35893 | E761: 35921 | F761: 35898 | G761: 2 | H761: 202.24 | I761: Princesa Isabel Vinhos | J761: Estrada da sade n. 58 | K761: Lisboa | L761: NULL | M761: 1756 | N761: Portugal | O761: =VLOOKUP(orders[[#This Row],[OrderID]],Table15[],4,FALSE) -> 54 | P761: =VLOOKUP(orders[[#This Row],[OrderID]],Table15[],2,FALSE) -> 2633.9 | Q761: =VLOOKUP(orders[[#This Row],[EmployeeID]],employee_territory[],2,FALSE) -> 19428 | R761: =VLOOKUP(orders[[#This Row],[Territory]],territories[],4,FALSE) -> Northern | S761: =VLOOKUP(orders[[#This Row],[ShipVia]],shippers[],2,FALSE) -> United Package | T761: =YEAR(orders[[#This Row],[OrderDate]]) -> 1998 | U761: =MONTH(orders[[#This Row],[OrderDate]]) -> 4
A762: 11008 | B762: ERNSH | C762: 7 | D762: 35893 | E762: 35921 | G762: 3 | H762: 79.46 | I762: Ernst Handel | J762: Kirchgasse 6 | K762: Graz | L762: NULL | M762: 8010 | N762: Austria | O762: =VLOOKUP(orders[[#This Row],[OrderID]],Table15[],4,FALSE) -> 181 | P762: =VLOOKUP(orders[[#This Row],[OrderID]],Table15[],2,FALSE) -> 4903.5 | Q762: =VLOOKUP(orders[[#This Row],[EmployeeID]],employee_territory[],2,FALSE) -> 60179 | R762: =VLOOKUP(orders[[#This Row],[Territory]],territories[],4,FALSE) -> Westerns | S762: =VLOOKUP(orders[[#This Row],[ShipVia]],shippers[],2,FALSE) -> Federal Shipping | T762: =YEAR(orders[[#This Row],[OrderDate]]) -> 1998 | U762: =MONTH(orders[[#This Row],[OrderDate]]) -> 4
A763: 11009 | B763: GODOS | C763: 2 | D763: 35893 | E763: 35921 | F763: 35895 | G763: 1 | H763: 59.11 | I763: Godos Cocina Tpica | J763: C/ Romero, 33 | K763: Sevilla | L763: NULL | M763: 41101 | N763: Spain | O763: =VLOOKUP(orders[[#This Row],[OrderID]],Table15[],4,FALSE) -> 39 | P763: =VLOOKUP(orders[[#This Row],[OrderID]],Table15[],2,FALSE) -> 702 | Q763: =VLOOKUP(orders[[#This Row],[EmployeeID]],employee_territory[],2,FALSE) -> 1581 | R763: =VLOOKUP(orders[[#This Row],[Territory]],territories[],4,FALSE) -> Eastern | S763: =VLOOKUP(orders[[#This Row],[ShipVia]],shippers[],2,FALSE) -> Speedy Express | T763: =YEAR(orders[[#This Row],[OrderDate]]) -> 1998 | U763: =MONTH(orders[[#This Row],[OrderDate]]) -> 4
A764: 11010 | B764: REGGC | C764: 2 | D764: 35894 | E764: 35922 | F764: 35906 | G764: 2 | H764: 28.71 | I764: Reggiani Caseifici | J764: Strada Provinciale 124 | K764: Reggio Emilia | L764: NULL | M764: 42100 | N764: Italy | O764: =VLOOKUP(orders[[#This Row],[OrderID]],Table15[],4,FALSE) -> 30 | P764: =VLOOKUP(orders[[#This Row],[OrderID]],Table15[],2,FALSE) -> 645 | Q764: =VLOOKUP(orders[[#This Row],[EmployeeID]],employee_territory[],2,FALSE) -> 1581 | R764: =VLOOKUP(orders[[#This Row],[Territory]],territories[],4,FALSE) -> Eastern | S764: =VLOOKUP(orders[[#This Row],[ShipVia]],shippers[],2,FALSE) -> United Package | T764: =YEAR(orders[[#This Row],[OrderDate]]) -> 1998 | U764: =MONTH(orders[[#This Row],[OrderDate]]) -> 4
A765: 11011 | B765: ALFKI | C765: 3 | D765: 35894 | E765: 35922 | F765: 35898 | G765: 1 | H765: 1.21 | I765: Alfred-s Futterkiste | J765: Obere Str. 57 | K765: Berlin | L765: NULL | M765: 12209 | N765: Germany | O765: =VLOOKUP(orders[[#This Row],[OrderID]],Table15[],4,FALSE) -> 60 | P765: =VLOOKUP(orders[[#This Row],[OrderID]],Table15[],2,FALSE) -> 960 | Q765: =VLOOKUP(orders[[#This Row],[EmployeeID]],employee_territory[],2,FALSE) -> 30346 | R765: =VLOOKUP(orders[[#This Row],[Territory]],territories[],4,FALSE) -> Southern | S765: =VLOOKUP(orders[[#This Row],[ShipVia]],shippers[],2,FALSE) -> Speedy Express | T765: =YEAR(orders[[#This Row],[OrderDate]]) -> 1998 | U765: =MONTH(orders[[#This Row],[OrderDate]]) -> 4
A766: 11012 | B766: FRANK | C766: 1 | D766: 35894 | E766: 35908 | F766: 35902 | G766: 3 | H766: 242.95 | I766: Frankenversand | J766: Berliner Platz 43 | K766: Mnchen | L766: NULL | M766: 80805 | N766: Germany | O766: =VLOOKUP(orders[[#This Row],[OrderID]],Table15[],4,FALSE) -> 146 | P766: =VLOOKUP(orders[[#This Row],[OrderID]],Table15[],2,FALSE) -> 2974 | Q766: =VLOOKUP(orders[[#This Row],[EmployeeID]],employee_territory[],2,FALSE) -> 6897 | R766: =VLOOKUP(orders[[#This Row],[Territory]],territories[],4,FALSE) -> Eastern | S766: =VLOOKUP(orders[[#This Row],[ShipVia]],shippers[],2,FALSE) -> Federal Shipping | T766: =YEAR(orders[[#This Row],[OrderDate]]) -> 1998 | U766: =MONTH(orders[[#This Row],[OrderDate]]) -> 4
A767: 11013 | B767: ROMEY | C767: 2 | D767: 35894 | E767: 35922 | F767: 35895 | G767: 1 | H767: 32.99 | I767: Romero y tomillo | J767: Gran Va, 1 | K767: Madrid | L767: NULL | M767: 28001 | N767: Spain | O767: =VLOOKUP(orders[[#This Row],[OrderID]],Table15[],4,FALSE) -> 36 | P767: =VLOOKUP(orders[[#This Row],[OrderID]],Table15[],2,FALSE) -> 361 | Q767: =VLOOKUP(orders[[#This Row],[EmployeeID]],employee_territory[],2,FALSE) -> 1581 | R767: =VLOOKUP(orders[[#This Row],[Territory]],territories[],4,FALSE) -> Eastern | S767: =VLOOKUP(orders[[#This Row],[ShipVia]],shippers[],2,FALSE) -> Speedy Express | T767: =YEAR(orders[[#This Row],[OrderDate]]) -> 1998 | U767: =MONTH(orders[[#This Row],[OrderDate]]) -> 4
A768: 11014 | B768: LINOD | C768: 2 | D768: 35895 | E768: 35923 | F768: 35900 | G768: 3 | H768: 23.6 | I768: LINO-Delicateses | J768: Ave. 5 de Mayo Porlamar | K768: I. de Margarita | L768: Nueva Esparta | M768: 4980 | N768: Venezuela | O768: =VLOOKUP(orders[[#This Row],[OrderID]],Table15[],4,FALSE) -> 28 | P768: =VLOOKUP(orders[[#This Row],[OrderID]],Table15[],2,FALSE) -> 270.2 | Q768: =VLOOKUP(orders[[#This Row],[EmployeeID]],employee_territory[],2,FALSE) -> 1581 | R768: =VLOOKUP(orders[[#This Row],[Territory]],territories[],4,FALSE) -> Eastern | S768: =VLOOKUP(orders[[#This Row],[ShipVia]],shippers[],2,FALSE) -> Federal Shipping | T768: =YEAR(orders[[#This Row],[OrderDate]]) -> 1998 | U768: =MONTH(orders[[#This Row],[OrderDate]]) -> 4
A769: 11015 | B769: SANTG | C769: 2 | D769: 35895 | E769: 35909 | F769: 35905 | G769: 2 | H769: 4.62 | I769: Sant Gourmet | J769: Erling Skakkes gate 78 | K769: Stavern | L769: NULL | M769: 4110 | N769: Norway | O769: =VLOOKUP(orders[[#This Row],[OrderID]],Table15[],4,FALSE) -> 33 | P769: =VLOOKUP(orders[[#This Row],[OrderID]],Table15[],2,FALSE) -> 622.35 | Q769: =VLOOKUP(orders[[#This Row],[EmployeeID]],employee_territory[],2,FALSE) -> 1581 | R769: =VLOOKUP(orders[[#This Row],[Territory]],territories[],4,FALSE) -> Eastern | S769: =VLOOKUP(orders[[#This Row],[ShipVia]],shippers[],2,FALSE) -> United Package | T769: =YEAR(orders[[#This Row],[OrderDate]]) -> 1998 | U769: =MONTH(orders[[#This Row],[OrderDate]]) -> 4
A770: 11016 | B770: AROUT | C770: 9 | D770: 35895 | E770: 35923 | F770: 35898 | G770: 2 | H770: 33.8 | I770: Around the Horn | J770: Brook Farm Stratford St. Mary | K770: Colchester | L770: Essex | M770: CO7 6JX | N770: UK | O770: =VLOOKUP(orders[[#This Row],[OrderID]],Table15[],4,FALSE) -> 31 | P770: =VLOOKUP(orders[[#This Row],[OrderID]],Table15[],2,FALSE) -> 491.5 | Q770: =VLOOKUP(orders[[#This Row],[EmployeeID]],employee_territory[],2,FALSE) -> 3049 | R770: =VLOOKUP(orders[[#This Row],[Territory]],territories[],4,FALSE) -> Northern | S770: =VLOOKUP(orders[[#This Row],[ShipVia]],shippers[],2,FALSE) -> United Package | T770: =YEAR(orders[[#This Row],[OrderDate]]) -> 1998 | U770: =MONTH(orders[[#This Row],[OrderDate]]) -> 4
A771: 11017 | B771: ERNSH | C771: 9 | D771: 35898 | E771: 35926 | F771: 35905 | G771: 2 | H771: 754.26 | I771: Ernst Handel | J771: Kirchgasse 6 | K771: Graz | L771: NULL | M771: 8010 | N771: Austria | O771: =VLOOKUP(orders[[#This Row],[OrderID]],Table15[],4,FALSE) -> 165 | P771: =VLOOKUP(orders[[#This Row],[OrderID]],Table15[],2,FALSE) -> 6750 | Q771: =VLOOKUP(orders[[#This Row],[EmployeeID]],employee_territory[],2,FALSE) -> 3049 | R771: =VLOOKUP(orders[[#This Row],[Territory]],territories[],4,FALSE) -> Northern | S771: =VLOOKUP(orders[[#This Row],[ShipVia]],shippers[],2,FALSE) -> United Package | T771: =YEAR(orders[[#This Row],[OrderDate]]) -> 1998 | U771: =MONTH(orders[[#This Row],[OrderDate]]) -> 4
A772: 11018 | B772: LONEP | C772: 4 | D772: 35898 | E772: 35926 | F772: 35901 | G772: 2 | H772: 11.65 | I772: Lonesome Pine Restaurant | J772: 89 Chiaroscuro Rd. | K772: Portland | L772: OR | M772: 97219 | N772: USA | O772: =VLOOKUP(orders[[#This Row],[OrderID]],Table15[],4,FALSE) -> 35 | P772: =VLOOKUP(orders[[#This Row],[OrderID]],Table15[],2,FALSE) -> 1575 | Q772: =VLOOKUP(orders[[#This Row],[EmployeeID]],employee_territory[],2,FALSE) -> 20852 | R772: =VLOOKUP(orders[[#This Row],[Territory]],territories[],4,FALSE) -> Eastern | S772: =VLOOKUP(orders[[#This Row],[ShipVia]],shippers[],2,FALSE) -> United Package | T772: =YEAR(orders[[#This Row],[OrderDate]]) -> 1998 | U772: =MONTH(orders[[#This Row],[OrderDate]]) -> 4
A773: 11019 | B773: RANCH | C773: 6 | D773: 35898 | E773: 35926 | G773: 3 | H773: 3.17 | I773: Rancho grande | J773: Av. del Libertador 900 | K773: Buenos Aires | L773: NULL | M773: 1010 | N773: Argentina | O773: =VLOOKUP(orders[[#This Row],[OrderID]],Table15[],4,FALSE) -> 5 | P773: =VLOOKUP(orders[[#This Row],[OrderID]],Table15[],2,FALSE) -> 76 | Q773: =VLOOKUP(orders[[#This Row],[EmployeeID]],employee_territory[],2,FALSE) -> 85014 | R773: =VLOOKUP(orders[[#This Row],[Territory]],territories[],4,FALSE) -> Westerns | S773: =VLOOKUP(orders[[#This Row],[ShipVia]],shippers[],2,FALSE) -> Federal Shipping | T773: =YEAR(orders[[#This Row],[OrderDate]]) -> 1998 | U773: =MONTH(orders[[#This Row],[OrderDate]]) -> 4
A774: 11020 | B774: OTTIK | C774: 2 | D774: 35899 | E774: 35927 | F774: 35901 | G774: 2 | H774: 43.3 | I774: Ottilies Kseladen | J774: Mehrheimerstr. 369 | K774: Kln | L774: NULL | M774: 50739 | N774: Germany | O774: =VLOOKUP(orders[[#This Row],[OrderID]],Table15[],4,FALSE) -> 24 | P774: =VLOOKUP(orders[[#This Row],[OrderID]],Table15[],2,FALSE) -> 744 | Q774: =VLOOKUP(orders[[#This Row],[EmployeeID]],employee_territory[],2,FALSE) -> 1581 | R774: =VLOOKUP(orders[[#This Row],[Territory]],territories[],4,FALSE) -> Eastern | S774: =VLOOKUP(orders[[#This Row],[ShipVia]],shippers[],2,FALSE) -> United Package | T774: =YEAR(orders[[#This Row],[OrderDate]]) -> 1998 | U774: =MONTH(orders[[#This Row],[OrderDate]]) -> 4
A775: 11021 | B775: QUICK | C775: 3 | D775: 35899 | E775: 35927 | F775: 35906 | G775: 1 | H775: 297.18 | I775: QUICK-Stop | J775: Taucherstrae 10 | K775: Cunewalde | L775: NULL | M775: 1307 | N775: Germany | O775: =VLOOKUP(orders[[#This Row],[OrderID]],Table15[],4,FALSE) -> 168 | P775: =VLOOKUP(orders[[#This Row],[OrderID]],Table15[],2,FALSE) -> 6941.49 | Q775: =VLOOKUP(orders[[#This Row],[EmployeeID]],employee_territory[],2,FALSE) -> 30346 | R775: =VLOOKUP(orders[[#This Row],[Territory]],territories[],4,FALSE) -> Southern | S775: =VLOOKUP(orders[[#This Row],[ShipVia]],shippers[],2,FALSE) -> Speedy Express | T775: =YEAR(orders[[#This Row],[OrderDate]]) -> 1998 | U775: =MONTH(orders[[#This Row],[OrderDate]]) -> 4
A776: 11022 | B776: HANAR | C776: 9 | D776: 35899 | E776: 35927 | F776: 35919 | G776: 2 | H776: 6.27 | I776: Hanari Carnes | J776: Rua do Pao, 67 | K776: Rio de Janeiro | L776: RJ | M776: 05454-876 | N776: Brazil | O776: =VLOOKUP(orders[[#This Row],[OrderID]],Table15[],4,FALSE) -> 65 | P776: =VLOOKUP(orders[[#This Row],[OrderID]],Table15[],2,FALSE) -> 1402 | Q776: =VLOOKUP(orders[[#This Row],[EmployeeID]],employee_territory[],2,FALSE) -> 3049 | R776: =VLOOKUP(orders[[#This Row],[Territory]],territories[],4,FALSE) -> Northern | S776: =VLOOKUP(orders[[#This Row],[ShipVia]],shippers[],2,FALSE) -> United Package | T776: =YEAR(orders[[#This Row],[OrderDate]]) -> 1998 | U776: =MONTH(orders[[#This Row],[OrderDate]]) -> 4
A777: 11023 | B777: BSBEV | C777: 1 | D777: 35899 | E777: 35913 | F777: 35909 | G777: 2 | H777: 123.83 | I777: B-s Beverages | J777: Fauntleroy Circus | K777: London | L777: NULL | M777: EC2 5NT | N777: UK | O777: =VLOOKUP(orders[[#This Row],[OrderID]],Table15[],4,FALSE) -> 34 | P777: =VLOOKUP(orders[[#This Row],[OrderID]],Table15[],2,FALSE) -> 1500 | Q777: =VLOOKUP(orders[[#This Row],[EmployeeID]],employee_territory[],2,FALSE) -> 6897 | R777: =VLOOKUP(orders[[#This Row],[Territory]],territories[],4,FALSE) -> Eastern | S777: =VLOOKUP(orders[[#This Row],[ShipVia]],shippers[],2,FALSE) -> United Package | T777: =YEAR(orders[[#This Row],[OrderDate]]) -> 1998 | U777: =MONTH(orders[[#This Row],[OrderDate]]) -> 4
A778: 11024 | B778: EASTC | C778: 4 | D778: 35900 | E778: 35928 | F778: 35905 | G778: 1 | H778: 74.36 | I778: Eastern Connection | J778: 35 King George | K778: London | L778: NULL | M778: WX3 6FW | N778: UK | O778: =VLOOKUP(orders[[#This Row],[OrderID]],Table15[],4,FALSE) -> 113 | P778: =VLOOKUP(orders[[#This Row],[OrderID]],Table15[],2,FALSE) -> 1966.81 | Q778: =VLOOKUP(orders[[#This Row],[EmployeeID]],employee_territory[],2,FALSE) -> 20852 | R778: =VLOOKUP(orders[[#This Row],[Territory]],territories[],4,FALSE) -> Eastern | S778: =VLOOKUP(orders[[#This Row],[ShipVia]],shippers[],2,FALSE) -> Speedy Express | T778: =YEAR(orders[[#This Row],[OrderDate]]) -> 1998 | U778: =MONTH(orders[[#This Row],[OrderDate]]) -> 4
...

Sheet Dashboard2
AR23: `

Sheet Dashboard

Sheet order_details (2)
A1: OrderID | B1: ProductID | C1: UnitPrice | D1: Quantity | E1: Discount | F1: Line Sale | G1: SupplierID | H1: Year | I1: ProductName | J1: SupplierName | K1: ShipCountry | L1: ShipVia | M1: ShipperName | N1: CustomerID | O1: Region | P1: CategoryID | Q1: CategoryName | R1: Month
A2: 10248 | B2: 11 | C2: 14 | D2: 12 | E2: 0 | F2: =order_details__2[[#This Row],[UnitPrice]]*order_details__2[[#This Row],[Quantity]] -> 168 | G2: =VLOOKUP(order_details__2[[#This Row],[ProductID]],products[],3,FALSE) -> 5 | H2: =VLOOKUP(order_details__2[[#This Row],[OrderID]],orders[],20,FALSE) -> 1996 | I2: =VLOOKUP(order_details__2[[#This Row],[ProductID]],products[],2,FALSE) -> Queso Cabrales | J2: =VLOOKUP(order_details__2[[#This Row],[SupplierID]],suppliers[],2,FALSE) -> Cooperativa de Quesos 'Las Cabras' | K2: =VLOOKUP(order_details__2[[#This Row],[OrderID]],orders[],14,FALSE) -> France | L2: =VLOOKUP(order_details__2[[#This Row],[OrderID]],orders[],7,FALSE) -> 3 | M2: =VLOOKUP(order_details__2[[#This Row],[ShipVia ]],shippers[],2,FALSE) -> Federal Shipping | N2: =VLOOKUP(order_details__2[[#This Row],[OrderID]],orders[],2,FALSE) -> VINET | O2: =VLOOKUP(order_details__2[[#This Row],[OrderID]],orders[],18,FALSE) -> Eastern | P2: =VLOOKUP(order_details__2[[#This Row],[ProductID]],products[],4,FALSE) -> 4 | Q2: =VLOOKUP(order_details__2[[#This Row],[CategoryID]],categories[],2,FALSE) -> Dairy Products | R2: =VLOOKUP(order_details__2[[#This Row],[OrderID]],orders[],21,FALSE) -> 7
A3: 10248 | B3: 42 | C3: 9.8 | D3: 10 | E3: 0 | F3: =order_details__2[[#This Row],[UnitPrice]]*order_details__2[[#This Row],[Quantity]] -> 98 | G3: =VLOOKUP(order_details__2[[#This Row],[ProductID]],products[],3,FALSE) -> 20 | H3: =VLOOKUP(order_details__2[[#This Row],[OrderID]],orders[],20,FALSE) -> 1996 | I3: =VLOOKUP(order_details__2[[#This Row],[ProductID]],products[],2,FALSE) -> Singaporean Hokkien Fried Mee | J3: =VLOOKUP(order_details__2[[#This Row],[SupplierID]],suppliers[],2,FALSE) -> Leka Trading | K3: =VLOOKUP(order_details__2[[#This Row],[OrderID]],orders[],14,FALSE) -> France | L3: =VLOOKUP(order_details__2[[#This Row],[OrderID]],orders[],7,FALSE) -> 3 | M3: =VLOOKUP(order_details__2[[#This Row],[ShipVia ]],shippers[],2,FALSE) -> Federal Shipping | N3: =VLOOKUP(order_details__2[[#This Row],[OrderID]],orders[],2,FALSE) -> VINET | O3: =VLOOKUP(order_details__2[[#This Row],[OrderID]],orders[],18,FALSE) -> Eastern | P3: =VLOOKUP(order_details__2[[#This Row],[ProductID]],products[],4,FALSE) -> 5 | Q3: =VLOOKUP(order_details__2[[#This Row],[CategoryID]],categories[],2,FALSE) -> Grains/Cereals | R3: =VLOOKUP(order_details__2[[#This Row],[OrderID]],orders[],21,FALSE) -> 7
A4: 10248 | B4: 72 | C4: 34.8 | D4: 5 | E4: 0 | F4: =order_details__2[[#This Row],[UnitPrice]]*order_details__2[[#This Row],[Quantity]] -> 174 | G4: =VLOOKUP(order_details__2[[#This Row],[ProductID]],products[],3,FALSE) -> 14 | H4: =VLOOKUP(order_details__2[[#This Row],[OrderID]],orders[],20,FALSE) -> 1996 | I4: =VLOOKUP(order_details__2[[#This Row],[ProductID]],products[],2,FALSE) -> Mozzarella di Giovanni | J4: =VLOOKUP(order_details__2[[#This Row],[SupplierID]],suppliers[],2,FALSE) -> Formaggi Fortini s.r.l. | K4: =VLOOKUP(order_details__2[[#This Row],[OrderID]],orders[],14,FALSE) -> France | L4: =VLOOKUP(order_details__2[[#This Row],[OrderID]],orders[],7,FALSE) -> 3 | M4: =VLOOKUP(order_details__2[[#This Row],[ShipVia ]],shippers[],2,FALSE) -> Federal Shipping | N4: =VLOOKUP(order_details__2[[#This Row],[OrderID]],orders[],2,FALSE) -> VINET | O4: =VLOOKUP(order_details__2[[#This Row],[OrderID]],orders[],18,FALSE) -> Eastern | P4: =VLOOKUP(order_details__2[[#This Row],[ProductID]],products[],4,FALSE) -> 4 | Q4: =VLOOKUP(order_details__2[[#This Row],[CategoryID]],categories[],2,FALSE) -> Dairy Products | R4: =VLOOKUP(order_details__2[[#This Row],[OrderID]],orders[],21,FALSE) -> 7
A5: 10249 | B5: 14 | C5: 18.6 | D5: 9 | E5: 0 | F5: =order_details__2[[#This Row],[UnitPrice]]*order_details__2[[#This Row],[Quantity]] -> 167.4 | G5: =VLOOKUP(order_details__2[[#This Row],[ProductID]],products[],3,FALSE) -> 6 | H5: =VLOOKUP(order_details__2[[#This Row],[OrderID]],orders[],20,FALSE) -> 1996 | I5: =VLOOKUP(order_details__2[[#This Row],[ProductID]],products[],2,FALSE) -> Tofu | J5: =VLOOKUP(order_details__2[[#This Row],[SupplierID]],suppliers[],2,FALSE) -> Mayumi's | K5: =VLOOKUP(order_details__2[[#This Row],[OrderID]],orders[],14,FALSE) -> Germany | L5: =VLOOKUP(order_details__2[[#This Row],[OrderID]],orders[],7,FALSE) -> 1 | M5: =VLOOKUP(order_details__2[[#This Row],[ShipVia ]],shippers[],2,FALSE) -> Speedy Express | N5: =VLOOKUP(order_details__2[[#This Row],[OrderID]],orders[],2,FALSE) -> TOMSP | O5: =VLOOKUP(order_details__2[[#This Row],[OrderID]],orders[],18,FALSE) -> Westerns | P5: =VLOOKUP(order_details__2[[#This Row],[ProductID]],products[],4,FALSE) -> 7 | Q5: =VLOOKUP(order_details__2[[#This Row],[CategoryID]],categories[],2,FALSE) -> Produce | R5: =VLOOKUP(order_details__2[[#This Row],[OrderID]],orders[],21,FALSE) -> 7
A6: 10249 | B6: 51 | C6: 42.4 | D6: 40 | E6: 0 | F6: =order_details__2[[#This Row],[UnitPrice]]*order_details__2[[#This Row],[Quantity]] -> 1696 | G6: =VLOOKUP(order_details__2[[#This Row],[ProductID]],products[],3,FALSE) -> 24 | H6: =VLOOKUP(order_details__2[[#This Row],[OrderID]],orders[],20,FALSE) -> 1996 | I6: =VLOOKUP(order_details__2[[#This Row],[ProductID]],products[],2,FALSE) -> Manjimup Dried Apples | J6: =VLOOKUP(order_details__2[[#This Row],[SupplierID]],suppliers[],2,FALSE) -> G'day, Mate | K6: =VLOOKUP(order_details__2[[#This Row],[OrderID]],orders[],14,FALSE) -> Germany | L6: =VLOOKUP(order_details__2[[#This Row],[OrderID]],orders[],7,FALSE) -> 1 | M6: =VLOOKUP(order_details__2[[#This Row],[ShipVia ]],shippers[],2,FALSE) -> Speedy Express | N6: =VLOOKUP(order_details__2[[#This Row],[OrderID]],orders[],2,FALSE) -> TOMSP | O6: =VLOOKUP(order_details__2[[#This Row],[OrderID]],orders[],18,FALSE) -> Westerns | P6: =VLOOKUP(order_details__2[[#This Row],[ProductID]],products[],4,FALSE) -> 7 | Q6: =VLOOKUP(order_details__2[[#This Row],[CategoryID]],categories[],2,FALSE) -> Produce | R6: =VLOOKUP(order_details__2[[#This Row],[OrderID]],orders[],21,FALSE) -> 7
A7: 10250 | B7: 41 | C7: 7.7 | D7: 10 | E7: 0 | F7: =order_details__2[[#This Row],[UnitPrice]]*order_details__2[[#This Row],[Quantity]] -> 77 | G7: =VLOOKUP(order_details__2[[#This Row],[ProductID]],products[],3,FALSE) -> 19 | H7: =VLOOKUP(order_details__2[[#This Row],[OrderID]],orders[],20,FALSE) -> 1996 | I7: =VLOOKUP(order_details__2[[#This Row],[ProductID]],products[],2,FALSE) -> Jack's New England Clam Chowder | J7: =VLOOKUP(order_details__2[[#This Row],[SupplierID]],suppliers[],2,FALSE) -> New England Seafood Cannery | K7: =VLOOKUP(order_details__2[[#This Row],[OrderID]],orders[],14,FALSE) -> Brazil | L7: =VLOOKUP(order_details__2[[#This Row],[OrderID]],orders[],7,FALSE) -> 2 | M7: =VLOOKUP(order_details__2[[#This Row],[ShipVia ]],shippers[],2,FALSE) -> United Package | N7: =VLOOKUP(order_details__2[[#This Row],[OrderID]],orders[],2,FALSE) -> HANAR | O7: =VLOOKUP(order_details__2[[#This Row],[OrderID]],orders[],18,FALSE) -> Eastern | P7: =VLOOKUP(order_details__2[[#This Row],[ProductID]],products[],4,FALSE) -> 8 | Q7: =VLOOKUP(order_details__2[[#This Row],[CategoryID]],categories[],2,FALSE) -> Seafood | R7: =VLOOKUP(order_details__2[[#This Row],[OrderID]],orders[],21,FALSE) -> 7
A8: 10250 | B8: 51 | C8: 42.4 | D8: 35 | E8: 0 | F8: =order_details__2[[#This Row],[UnitPrice]]*order_details__2[[#This Row],[Quantity]] -> 1484 | G8: =VLOOKUP(order_details__2[[#This Row],[ProductID]],products[],3,FALSE) -> 24 | H8: =VLOOKUP(order_details__2[[#This Row],[OrderID]],orders[],20,FALSE) -> 1996 | I8: =VLOOKUP(order_details__2[[#This Row],[ProductID]],products[],2,FALSE) -> Manjimup Dried Apples | J8: =VLOOKUP(order_details__2[[#This Row],[SupplierID]],suppliers[],2,FALSE) -> G'day, Mate | K8: =VLOOKUP(order_details__2[[#This Row],[OrderID]],orders[],14,FALSE) -> Brazil | L8: =VLOOKUP(order_details__2[[#This Row],[OrderID]],orders[],7,FALSE) -> 2 | M8: =VLOOKUP(order_details__2[[#This Row],[ShipVia ]],shippers[],2,FALSE) -> United Package | N8: =VLOOKUP(order_details__2[[#This Row],[OrderID]],orders[],2,FALSE) -> HANAR | O8: =VLOOKUP(order_details__2[[#This Row],[OrderID]],orders[],18,FALSE) -> Eastern | P8: =VLOOKUP(order_details__2[[#This Row],[ProductID]],products[],4,FALSE) -> 7 | Q8: =VLOOKUP(order_details__2[[#This Row],[CategoryID]],categories[],2,FALSE) -> Produce | R8: =VLOOKUP(order_details__2[[#This Row],[OrderID]],orders[],21,FALSE) -> 7
A9: 10250 | B9: 65 | C9: 16.8 | D9: 15 | E9: 0 | F9: =order_details__2[[#This Row],[UnitPrice]]*order_details__2[[#This Row],[Quantity]] -> 252 | G9: =VLOOKUP(order_details__2[[#This Row],[ProductID]],products[],3,FALSE) -> 2 | H9: =VLOOKUP(order_details__2[[#This Row],[OrderID]],orders[],20,FALSE) -> 1996 | I9: =VLOOKUP(order_details__2[[#This Row],[ProductID]],products[],2,FALSE) -> Louisiana Fiery Hot Pepper Sauce | J9: =VLOOKUP(order_details__2[[#This Row],[SupplierID]],suppliers[],2,FALSE) -> New Orleans Cajun Delights | K9: =VLOOKUP(order_details__2[[#This Row],[OrderID]],orders[],14,FALSE) -> Brazil | L9: =VLOOKUP(order_details__2[[#This Row],[OrderID]],orders[],7,FALSE) -> 2 | M9: =VLOOKUP(order_details__2[[#This Row],[ShipVia ]],shippers[],2,FALSE) -> United Package | N9: =VLOOKUP(order_details__2[[#This Row],[OrderID]],orders[],2,FALSE) -> HANAR | O9: =VLOOKUP(order_details__2[[#This Row],[OrderID]],orders[],18,FALSE) -> Eastern | P9: =VLOOKUP(order_details__2[[#This Row],[ProductID]],products[],4,FALSE) -> 2 | Q9: =VLOOKUP(order_details__2[[#This Row],[CategoryID]],categories[],2,FALSE) -> Condiments | R9: =VLOOKUP(order_details__2[[#This Row],[OrderID]],orders[],21,FALSE) -> 7
A10: 10251 | B10: 22 | C10: 16.8 | D10: 6 | E10: 0 | F10: =order_details__2[[#This Row],[UnitPrice]]*order_details__2[[#This Row],[Quantity]] -> 100.8 | G10: =VLOOKUP(order_details__2[[#This Row],[ProductID]],products[],3,FALSE) -> 9 | H10: =VLOOKUP(order_details__2[[#This Row],[OrderID]],orders[],20,FALSE) -> 1996 | I10: =VLOOKUP(order_details__2[[#This Row],[ProductID]],products[],2,FALSE) -> Gustaf's Knckebrd | J10: =VLOOKUP(order_details__2[[#This Row],[SupplierID]],suppliers[],2,FALSE) -> PB Knckebrd AB | K10: =VLOOKUP(order_details__2[[#This Row],[OrderID]],orders[],14,FALSE) -> France | L10: =VLOOKUP(order_details__2[[#This Row],[OrderID]],orders[],7,FALSE) -> 1 | M10: =VLOOKUP(order_details__2[[#This Row],[ShipVia ]],shippers[],2,FALSE) -> Speedy Express | N10: =VLOOKUP(order_details__2[[#This Row],[OrderID]],orders[],2,FALSE) -> VICTE | O10: =VLOOKUP(order_details__2[[#This Row],[OrderID]],orders[],18,FALSE) -> Southern | P10: =VLOOKUP(order_details__2[[#This Row],[ProductID]],products[],4,FALSE) -> 5 | Q10: =VLOOKUP(order_details__2[[#This Row],[CategoryID]],categories[],2,FALSE) -> Grains/Cereals | R10: =VLOOKUP(order_details__2[[#This Row],[OrderID]],orders[],21,FALSE) -> 7
A11: 10251 | B11: 57 | C11: 15.6 | D11: 15 | E11: 0 | F11: =order_details__2[[#This Row],[UnitPrice]]*order_details__2[[#This Row],[Quantity]] -> 234 | G11: =VLOOKUP(order_details__2[[#This Row],[ProductID]],products[],3,FALSE) -> 26 | H11: =VLOOKUP(order_details__2[[#This Row],[OrderID]],orders[],20,FALSE) -> 1996 | I11: =VLOOKUP(order_details__2[[#This Row],[ProductID]],products[],2,FALSE) -> Ravioli Angelo | J11: =VLOOKUP(order_details__2[[#This Row],[SupplierID]],suppliers[],2,FALSE) -> Pasta Buttini s.r.l. | K11: =VLOOKUP(order_details__2[[#This Row],[OrderID]],orders[],14,FALSE) -> France | L11: =VLOOKUP(order_details__2[[#This Row],[OrderID]],orders[],7,FALSE) -> 1 | M11: =VLOOKUP(order_details__2[[#This Row],[ShipVia ]],shippers[],2,FALSE) -> Speedy Express | N11: =VLOOKUP(order_details__2[[#This Row],[OrderID]],orders[],2,FALSE) -> VICTE | O11: =VLOOKUP(order_details__2[[#This Row],[OrderID]],orders[],18,FALSE) -> Southern | P11: =VLOOKUP(order_details__2[[#This Row],[ProductID]],products[],4,FALSE) -> 5 | Q11: =VLOOKUP(order_details__2[[#This Row],[CategoryID]],categories[],2,FALSE) -> Grains/Cereals | R11: =VLOOKUP(order_details__2[[#This Row],[OrderID]],orders[],21,FALSE) -> 7 | Y11: I have to create the 4 graphs again
A12: 10251 | B12: 65 | C12: 16.8 | D12: 20 | E12: 0 | F12: =order_details__2[[#This Row],[UnitPrice]]*order_details__2[[#This Row],[Quantity]] -> 336 | G12: =VLOOKUP(order_details__2[[#This Row],[ProductID]],products[],3,FALSE) -> 2 | H12: =VLOOKUP(order_details__2[[#This Row],[OrderID]],orders[],20,FALSE) -> 1996 | I12: =VLOOKUP(order_details__2[[#This Row],[ProductID]],products[],2,FALSE) -> Louisiana Fiery Hot Pepper Sauce | J12: =VLOOKUP(order_details__2[[#This Row],[SupplierID]],suppliers[],2,FALSE) -> New Orleans Cajun Delights | K12: =VLOOKUP(order_details__2[[#This Row],[OrderID]],orders[],14,FALSE) -> France | L12: =VLOOKUP(order_details__2[[#This Row],[OrderID]],orders[],7,FALSE) -> 1 | M12: =VLOOKUP(order_details__2[[#This Row],[ShipVia ]],shippers[],2,FALSE) -> Speedy Express | N12: =VLOOKUP(order_details__2[[#This Row],[OrderID]],orders[],2,FALSE) -> VICTE | O12: =VLOOKUP(order_details__2[[#This Row],[OrderID]],orders[],18,FALSE) -> Southern | P12: =VLOOKUP(order_details__2[[#This Row],[ProductID]],products[],4,FALSE) -> 2 | Q12: =VLOOKUP(order_details__2[[#This Row],[CategoryID]],categories[],2,FALSE) -> Condiments | R12: =VLOOKUP(order_details__2[[#This Row],[OrderID]],orders[],21,FALSE) -> 7 | Y12: since this would be enabling slicers
A13: 10252 | B13: 20 | C13: 64.8 | D13: 40 | E13: 0 | F13: =order_details__2[[#This Row],[UnitPrice]]*order_details__2[[#This Row],[Quantity]] -> 2592 | G13: =VLOOKUP(order_details__2[[#This Row],[ProductID]],products[],3,FALSE) -> 8 | H13: =VLOOKUP(order_details__2[[#This Row],[OrderID]],orders[],20,FALSE) -> 1996 | I13: =VLOOKUP(order_details__2[[#This Row],[ProductID]],products[],2,FALSE) -> Sir Rodney's Marmalade | J13: =VLOOKUP(order_details__2[[#This Row],[SupplierID]],suppliers[],2,FALSE) -> Specialty Biscuits, Ltd. | K13: =VLOOKUP(order_details__2[[#This Row],[OrderID]],orders[],14,FALSE) -> Belgium | L13: =VLOOKUP(order_details__2[[#This Row],[OrderID]],orders[],7,FALSE) -> 2 | M13: =VLOOKUP(order_details__2[[#This Row],[ShipVia ]],shippers[],2,FALSE) -> United Package | N13: =VLOOKUP(order_details__2[[#This Row],[OrderID]],orders[],2,FALSE) -> SUPRD | O13: =VLOOKUP(order_details__2[[#This Row],[OrderID]],orders[],18,FALSE) -> Eastern | P13: =VLOOKUP(order_details__2[[#This Row],[ProductID]],products[],4,FALSE) -> 3 | Q13: =VLOOKUP(order_details__2[[#This Row],[CategoryID]],categories[],2,FALSE) -> Confections | R13: =VLOOKUP(order_details__2[[#This Row],[OrderID]],orders[],21,FALSE) -> 7
A14: 10252 | B14: 33 | C14: 2 | D14: 25 | E14: 0 | F14: =order_details__2[[#This Row],[UnitPrice]]*order_details__2[[#This Row],[Quantity]] -> 50 | G14: =VLOOKUP(order_details__2[[#This Row],[ProductID]],products[],3,FALSE) -> 15 | H14: =VLOOKUP(order_details__2[[#This Row],[OrderID]],orders[],20,FALSE) -> 1996 | I14: =VLOOKUP(order_details__2[[#This Row],[ProductID]],products[],2,FALSE) -> Geitost | J14: =VLOOKUP(order_details__2[[#This Row],[SupplierID]],suppliers[],2,FALSE) -> Norske Meierier | K14: =VLOOKUP(order_details__2[[#This Row],[OrderID]],orders[],14,FALSE) -> Belgium | L14: =VLOOKUP(order_details__2[[#This Row],[OrderID]],orders[],7,FALSE) -> 2 | M14: =VLOOKUP(order_details__2[[#This Row],[ShipVia ]],shippers[],2,FALSE) -> United Package | N14: =VLOOKUP(order_details__2[[#This Row],[OrderID]],orders[],2,FALSE) -> SUPRD | O14: =VLOOKUP(order_details__2[[#This Row],[OrderID]],orders[],18,FALSE) -> Eastern | P14: =VLOOKUP(order_details__2[[#This Row],[ProductID]],products[],4,FALSE) -> 4 | Q14: =VLOOKUP(order_details__2[[#This Row],[CategoryID]],categories[],2,FALSE) -> Dairy Products | R14: =VLOOKUP(order_details__2[[#This Row],[OrderID]],orders[],21,FALSE) -> 7
A15: 10252 | B15: 60 | C15: 27.2 | D15: 40 | E15: 0 | F15: =order_details__2[[#This Row],[UnitPrice]]*order_details__2[[#This Row],[Quantity]] -> 1088 | G15: =VLOOKUP(order_details__2[[#This Row],[ProductID]],products[],3,FALSE) -> 28 | H15: =VLOOKUP(order_details__2[[#This Row],[OrderID]],orders[],20,FALSE) -> 1996 | I15: =VLOOKUP(order_details__2[[#This Row],[ProductID]],products[],2,FALSE) -> Camembert Pierrot | J15: =VLOOKUP(order_details__2[[#This Row],[SupplierID]],suppliers[],2,FALSE) -> Gai pturage | K15: =VLOOKUP(order_details__2[[#This Row],[OrderID]],orders[],14,FALSE) -> Belgium | L15: =VLOOKUP(order_details__2[[#This Row],[OrderID]],orders[],7,FALSE) -> 2 | M15: =VLOOKUP(order_details__2[[#This Row],[ShipVia ]],shippers[],2,FALSE) -> United Package | N15: =VLOOKUP(order_details__2[[#This Row],[OrderID]],orders[],2,FALSE) -> SUPRD | O15: =VLOOKUP(order_details__2[[#This Row],[OrderID]],orders[],18,FALSE) -> Eastern | P15: =VLOOKUP(order_details__2[[#This Row],[ProductID]],products[],4,FALSE) -> 4 | Q15: =VLOOKUP(order_details__2[[#This Row],[CategoryID]],categories[],2,FALSE) -> Dairy Products | R15: =VLOOKUP(order_details__2[[#This Row],[OrderID]],orders[],21,FALSE) -> 7
